[2023-09-10T18:01:10.701+0000] {taskinstance.py:1171} INFO - Dependencies all met for <TaskInstance: weather_pipeline.move_data manual__2023-09-10T17:48:34.883916+00:00 [queued]>
[2023-09-10T18:01:10.712+0000] {taskinstance.py:1171} INFO - Dependencies all met for <TaskInstance: weather_pipeline.move_data manual__2023-09-10T17:48:34.883916+00:00 [queued]>
[2023-09-10T18:01:10.712+0000] {taskinstance.py:1368} INFO - 
--------------------------------------------------------------------------------
[2023-09-10T18:01:10.712+0000] {taskinstance.py:1369} INFO - Starting attempt 4 of 4
[2023-09-10T18:01:10.712+0000] {taskinstance.py:1370} INFO - 
--------------------------------------------------------------------------------
[2023-09-10T18:01:10.728+0000] {taskinstance.py:1389} INFO - Executing <Task(PythonOperator): move_data> on 2023-09-10 17:48:34.883916+00:00
[2023-09-10T18:01:10.736+0000] {standard_task_runner.py:52} INFO - Started process 678 to run task
[2023-09-10T18:01:10.740+0000] {standard_task_runner.py:79} INFO - Running: ['***', 'tasks', 'run', 'weather_pipeline', 'move_data', 'manual__2023-09-10T17:48:34.883916+00:00', '--job-id', '43', '--raw', '--subdir', 'DAGS_FOLDER/weather_dag.py', '--cfg-path', '/tmp/tmpk1ida3ot', '--error-file', '/tmp/tmplg59huym']
[2023-09-10T18:01:10.741+0000] {standard_task_runner.py:80} INFO - Job 43: Subtask move_data
[2023-09-10T18:01:10.813+0000] {task_command.py:371} INFO - Running <TaskInstance: weather_pipeline.move_data manual__2023-09-10T17:48:34.883916+00:00 [running]> on host afe1e7d20f24
[2023-09-10T18:01:10.896+0000] {taskinstance.py:1583} INFO - Exporting the following env vars:
AIRFLOW_CTX_DAG_OWNER=thinh pham
AIRFLOW_CTX_DAG_ID=weather_pipeline
AIRFLOW_CTX_TASK_ID=move_data
AIRFLOW_CTX_EXECUTION_DATE=2023-09-10T17:48:34.883916+00:00
AIRFLOW_CTX_TRY_NUMBER=4
AIRFLOW_CTX_DAG_RUN_ID=manual__2023-09-10T17:48:34.883916+00:00
[2023-09-10T18:01:12.227+0000] {logging_mixin.py:115} INFO - file containe weather data has been create with name Current_weather_data_10092023.csv
[2023-09-10T18:01:12.234+0000] {taskinstance.py:1902} ERROR - Task failed with exception
Traceback (most recent call last):
  File "/home/airflow/.local/lib/python3.7/site-packages/airflow/operators/python.py", line 171, in execute
    return_value = self.execute_callable()
  File "/home/airflow/.local/lib/python3.7/site-packages/airflow/operators/python.py", line 189, in execute_callable
    return self.python_callable(*self.op_args, **self.op_kwargs)
  File "task/weather_extraction.py", line 87, in move_data_s3
    file_name  # Specify the S3 object key (file name)
  File "/home/airflow/.local/lib/python3.7/site-packages/boto3/s3/inject.py", line 148, in upload_file
    callback=Callback,
  File "/home/airflow/.local/lib/python3.7/site-packages/boto3/s3/transfer.py", line 288, in upload_file
    future.result()
  File "/home/airflow/.local/lib/python3.7/site-packages/s3transfer/futures.py", line 103, in result
    return self._coordinator.result()
  File "/home/airflow/.local/lib/python3.7/site-packages/s3transfer/futures.py", line 266, in result
    raise self._exception
  File "/home/airflow/.local/lib/python3.7/site-packages/s3transfer/tasks.py", line 139, in __call__
    return self._execute_main(kwargs)
  File "/home/airflow/.local/lib/python3.7/site-packages/s3transfer/tasks.py", line 162, in _execute_main
    return_value = self._main(**kwargs)
  File "/home/airflow/.local/lib/python3.7/site-packages/s3transfer/upload.py", line 758, in _main
    client.put_object(Bucket=bucket, Key=key, Body=body, **extra_args)
  File "/home/airflow/.local/lib/python3.7/site-packages/botocore/client.py", line 508, in _api_call
    return self._make_api_call(operation_name, kwargs)
  File "/home/airflow/.local/lib/python3.7/site-packages/botocore/client.py", line 899, in _make_api_call
    operation_model, request_dict, request_context
  File "/home/airflow/.local/lib/python3.7/site-packages/botocore/client.py", line 921, in _make_request
    return self._endpoint.make_request(operation_model, request_dict)
  File "/home/airflow/.local/lib/python3.7/site-packages/botocore/endpoint.py", line 119, in make_request
    return self._send_request(request_dict, operation_model)
  File "/home/airflow/.local/lib/python3.7/site-packages/botocore/endpoint.py", line 198, in _send_request
    request = self.create_request(request_dict, operation_model)
  File "/home/airflow/.local/lib/python3.7/site-packages/botocore/endpoint.py", line 137, in create_request
    operation_name=operation_model.name,
  File "/home/airflow/.local/lib/python3.7/site-packages/botocore/hooks.py", line 412, in emit
    return self._emitter.emit(aliased_event_name, **kwargs)
  File "/home/airflow/.local/lib/python3.7/site-packages/botocore/hooks.py", line 256, in emit
    return self._emit(event_name, kwargs)
  File "/home/airflow/.local/lib/python3.7/site-packages/botocore/hooks.py", line 239, in _emit
    response = handler(**kwargs)
  File "/home/airflow/.local/lib/python3.7/site-packages/botocore/signers.py", line 103, in handler
    return self.sign(operation_name, request)
  File "/home/airflow/.local/lib/python3.7/site-packages/botocore/signers.py", line 187, in sign
    auth.add_auth(request)
  File "/home/airflow/.local/lib/python3.7/site-packages/botocore/auth.py", line 407, in add_auth
    raise NoCredentialsError()
botocore.exceptions.NoCredentialsError: Unable to locate credentials
[2023-09-10T18:01:12.248+0000] {taskinstance.py:1412} INFO - Marking task as FAILED. dag_id=weather_pipeline, task_id=move_data, execution_date=20230910T174834, start_date=20230910T180110, end_date=20230910T180112
[2023-09-10T18:01:12.260+0000] {standard_task_runner.py:97} ERROR - Failed to execute job 43 for task move_data (Unable to locate credentials; 678)
[2023-09-10T18:01:12.275+0000] {local_task_job.py:156} INFO - Task exited with return code 1
[2023-09-10T18:01:12.310+0000] {local_task_job.py:279} INFO - 0 downstream tasks scheduled from follow-on schedule check
