[2023-09-10T17:53:44.027+0000] {taskinstance.py:1171} INFO - Dependencies all met for <TaskInstance: weather_pipeline.move_data manual__2023-09-10T17:48:34.883916+00:00 [queued]>
[2023-09-10T17:53:44.038+0000] {taskinstance.py:1171} INFO - Dependencies all met for <TaskInstance: weather_pipeline.move_data manual__2023-09-10T17:48:34.883916+00:00 [queued]>
[2023-09-10T17:53:44.038+0000] {taskinstance.py:1368} INFO - 
--------------------------------------------------------------------------------
[2023-09-10T17:53:44.038+0000] {taskinstance.py:1369} INFO - Starting attempt 2 of 2
[2023-09-10T17:53:44.038+0000] {taskinstance.py:1370} INFO - 
--------------------------------------------------------------------------------
[2023-09-10T17:53:44.053+0000] {taskinstance.py:1389} INFO - Executing <Task(PythonOperator): move_data> on 2023-09-10 17:48:34.883916+00:00
[2023-09-10T17:53:44.061+0000] {standard_task_runner.py:52} INFO - Started process 333 to run task
[2023-09-10T17:53:44.065+0000] {standard_task_runner.py:79} INFO - Running: ['***', 'tasks', 'run', 'weather_pipeline', 'move_data', 'manual__2023-09-10T17:48:34.883916+00:00', '--job-id', '41', '--raw', '--subdir', 'DAGS_FOLDER/weather_dag.py', '--cfg-path', '/tmp/tmp1d3a1gv4', '--error-file', '/tmp/tmp8xruthww']
[2023-09-10T17:53:44.067+0000] {standard_task_runner.py:80} INFO - Job 41: Subtask move_data
[2023-09-10T17:53:44.141+0000] {task_command.py:371} INFO - Running <TaskInstance: weather_pipeline.move_data manual__2023-09-10T17:48:34.883916+00:00 [running]> on host afe1e7d20f24
[2023-09-10T17:53:44.225+0000] {taskinstance.py:1583} INFO - Exporting the following env vars:
AIRFLOW_CTX_DAG_OWNER=thinh pham
AIRFLOW_CTX_DAG_ID=weather_pipeline
AIRFLOW_CTX_TASK_ID=move_data
AIRFLOW_CTX_EXECUTION_DATE=2023-09-10T17:48:34.883916+00:00
AIRFLOW_CTX_TRY_NUMBER=2
AIRFLOW_CTX_DAG_RUN_ID=manual__2023-09-10T17:48:34.883916+00:00
[2023-09-10T17:53:45.561+0000] {logging_mixin.py:115} INFO - file containe weather data has been create with name Current_weather_data_10092023.csv
[2023-09-10T17:53:45.591+0000] {logging_mixin.py:115} INFO -      City      Description  ...  Sunset (Local Time)   Local Record Time
0  London  overcast clouds  ...  2023-09-10 18:28:46 2023-09-10 17:48:42

[1 rows x 10 columns]
[2023-09-10T17:53:45.593+0000] {taskinstance.py:1902} ERROR - Task failed with exception
Traceback (most recent call last):
  File "/home/airflow/.local/lib/python3.7/site-packages/airflow/operators/python.py", line 171, in execute
    return_value = self.execute_callable()
  File "/home/airflow/.local/lib/python3.7/site-packages/airflow/operators/python.py", line 189, in execute_callable
    return self.python_callable(*self.op_args, **self.op_kwargs)
  File "task/weather_extraction.py", line 87, in move_data_s3
    file_name  # Specify the S3 object key (file name)
  File "/home/airflow/.local/lib/python3.7/site-packages/boto3/s3/inject.py", line 148, in upload_file
    callback=Callback,
  File "/home/airflow/.local/lib/python3.7/site-packages/boto3/s3/transfer.py", line 288, in upload_file
    future.result()
  File "/home/airflow/.local/lib/python3.7/site-packages/s3transfer/futures.py", line 103, in result
    return self._coordinator.result()
  File "/home/airflow/.local/lib/python3.7/site-packages/s3transfer/futures.py", line 266, in result
    raise self._exception
  File "/home/airflow/.local/lib/python3.7/site-packages/s3transfer/tasks.py", line 269, in _main
    self._submit(transfer_future=transfer_future, **kwargs)
  File "/home/airflow/.local/lib/python3.7/site-packages/s3transfer/upload.py", line 585, in _submit
    upload_input_manager.provide_transfer_size(transfer_future)
  File "/home/airflow/.local/lib/python3.7/site-packages/s3transfer/upload.py", line 244, in provide_transfer_size
    self._osutil.get_file_size(transfer_future.meta.call_args.fileobj)
  File "/home/airflow/.local/lib/python3.7/site-packages/s3transfer/utils.py", line 247, in get_file_size
    return os.path.getsize(filename)
  File "/usr/local/lib/python3.7/genericpath.py", line 50, in getsize
    return os.stat(filename).st_size
FileNotFoundError: [Errno 2] No such file or directory: 'Current_weather_data_10092023.csv'
[2023-09-10T17:53:45.605+0000] {taskinstance.py:1412} INFO - Marking task as FAILED. dag_id=weather_pipeline, task_id=move_data, execution_date=20230910T174834, start_date=20230910T175344, end_date=20230910T175345
[2023-09-10T17:53:45.620+0000] {standard_task_runner.py:97} ERROR - Failed to execute job 41 for task move_data ([Errno 2] No such file or directory: 'Current_weather_data_10092023.csv'; 333)
[2023-09-10T17:53:45.643+0000] {local_task_job.py:156} INFO - Task exited with return code 1
[2023-09-10T17:53:45.680+0000] {local_task_job.py:279} INFO - 0 downstream tasks scheduled from follow-on schedule check
