[2023-09-10T13:24:17.524+0000] {taskinstance.py:1171} INFO - Dependencies all met for <TaskInstance: weather_pipeline.check_api_available manual__2023-09-10T13:20:09.970673+00:00 [queued]>
[2023-09-10T13:24:17.534+0000] {taskinstance.py:1171} INFO - Dependencies all met for <TaskInstance: weather_pipeline.check_api_available manual__2023-09-10T13:20:09.970673+00:00 [queued]>
[2023-09-10T13:24:17.534+0000] {taskinstance.py:1368} INFO - 
--------------------------------------------------------------------------------
[2023-09-10T13:24:17.534+0000] {taskinstance.py:1369} INFO - Starting attempt 2 of 3
[2023-09-10T13:24:17.534+0000] {taskinstance.py:1370} INFO - 
--------------------------------------------------------------------------------
[2023-09-10T13:24:17.550+0000] {taskinstance.py:1389} INFO - Executing <Task(PythonOperator): check_api_available> on 2023-09-10 13:20:09.970673+00:00
[2023-09-10T13:24:17.563+0000] {standard_task_runner.py:52} INFO - Started process 82 to run task
[2023-09-10T13:24:17.566+0000] {standard_task_runner.py:79} INFO - Running: ['***', 'tasks', 'run', 'weather_pipeline', 'check_api_available', 'manual__2023-09-10T13:20:09.970673+00:00', '--job-id', '16', '--raw', '--subdir', 'DAGS_FOLDER/weather_dag.py', '--cfg-path', '/tmp/tmp3s1br7sl', '--error-file', '/tmp/tmpxieefkwv']
[2023-09-10T13:24:17.567+0000] {standard_task_runner.py:80} INFO - Job 16: Subtask check_api_available
[2023-09-10T13:24:17.636+0000] {task_command.py:371} INFO - Running <TaskInstance: weather_pipeline.check_api_available manual__2023-09-10T13:20:09.970673+00:00 [running]> on host d11260bc41d1
[2023-09-10T13:24:17.723+0000] {taskinstance.py:1583} INFO - Exporting the following env vars:
AIRFLOW_CTX_DAG_OWNER=thinh pham
AIRFLOW_CTX_DAG_ID=weather_pipeline
AIRFLOW_CTX_TASK_ID=check_api_available
AIRFLOW_CTX_EXECUTION_DATE=2023-09-10T13:20:09.970673+00:00
AIRFLOW_CTX_TRY_NUMBER=2
AIRFLOW_CTX_DAG_RUN_ID=manual__2023-09-10T13:20:09.970673+00:00
[2023-09-10T13:24:17.725+0000] {taskinstance.py:1902} ERROR - Task failed with exception
Traceback (most recent call last):
  File "/home/airflow/.local/lib/python3.7/site-packages/airflow/operators/python.py", line 171, in execute
    return_value = self.execute_callable()
  File "/home/airflow/.local/lib/python3.7/site-packages/airflow/operators/python.py", line 189, in execute_callable
    return self.python_callable(*self.op_args, **self.op_kwargs)
TypeError: check_api_request() missing 1 required positional argument: 'api_url'
[2023-09-10T13:24:17.733+0000] {taskinstance.py:1412} INFO - Marking task as UP_FOR_RETRY. dag_id=weather_pipeline, task_id=check_api_available, execution_date=20230910T132009, start_date=20230910T132417, end_date=20230910T132417
[2023-09-10T13:24:17.746+0000] {standard_task_runner.py:97} ERROR - Failed to execute job 16 for task check_api_available (check_api_request() missing 1 required positional argument: 'api_url'; 82)
[2023-09-10T13:24:17.780+0000] {local_task_job.py:156} INFO - Task exited with return code 1
[2023-09-10T13:24:17.820+0000] {local_task_job.py:279} INFO - 0 downstream tasks scheduled from follow-on schedule check
