[2023-09-10T18:29:56.037+0000] {taskinstance.py:1171} INFO - Dependencies all met for <TaskInstance: weather_pipeline.move_data manual__2023-09-10T18:24:19.896302+00:00 [queued]>
[2023-09-10T18:29:56.048+0000] {taskinstance.py:1171} INFO - Dependencies all met for <TaskInstance: weather_pipeline.move_data manual__2023-09-10T18:24:19.896302+00:00 [queued]>
[2023-09-10T18:29:56.048+0000] {taskinstance.py:1368} INFO - 
--------------------------------------------------------------------------------
[2023-09-10T18:29:56.048+0000] {taskinstance.py:1369} INFO - Starting attempt 2 of 3
[2023-09-10T18:29:56.048+0000] {taskinstance.py:1370} INFO - 
--------------------------------------------------------------------------------
[2023-09-10T18:29:56.063+0000] {taskinstance.py:1389} INFO - Executing <Task(PythonOperator): move_data> on 2023-09-10 18:24:19.896302+00:00
[2023-09-10T18:29:56.071+0000] {standard_task_runner.py:52} INFO - Started process 2035 to run task
[2023-09-10T18:29:56.075+0000] {standard_task_runner.py:79} INFO - Running: ['***', 'tasks', 'run', 'weather_pipeline', 'move_data', 'manual__2023-09-10T18:24:19.896302+00:00', '--job-id', '53', '--raw', '--subdir', 'DAGS_FOLDER/weather_dag.py', '--cfg-path', '/tmp/tmp4in1x2w0', '--error-file', '/tmp/tmpqbt41xs0']
[2023-09-10T18:29:56.076+0000] {standard_task_runner.py:80} INFO - Job 53: Subtask move_data
[2023-09-10T18:29:56.152+0000] {task_command.py:371} INFO - Running <TaskInstance: weather_pipeline.move_data manual__2023-09-10T18:24:19.896302+00:00 [running]> on host afe1e7d20f24
[2023-09-10T18:29:56.236+0000] {taskinstance.py:1583} INFO - Exporting the following env vars:
AIRFLOW_CTX_DAG_OWNER=thinh pham
AIRFLOW_CTX_DAG_ID=weather_pipeline
AIRFLOW_CTX_TASK_ID=move_data
AIRFLOW_CTX_EXECUTION_DATE=2023-09-10T18:24:19.896302+00:00
AIRFLOW_CTX_TRY_NUMBER=2
AIRFLOW_CTX_DAG_RUN_ID=manual__2023-09-10T18:24:19.896302+00:00
[2023-09-10T18:29:56.547+0000] {taskinstance.py:1902} ERROR - Task failed with exception
Traceback (most recent call last):
  File "/home/airflow/.local/lib/python3.7/site-packages/airflow/operators/python.py", line 171, in execute
    return_value = self.execute_callable()
  File "/home/airflow/.local/lib/python3.7/site-packages/airflow/operators/python.py", line 189, in execute_callable
    return self.python_callable(*self.op_args, **self.op_kwargs)
  File "task/weather_extraction.py", line 87, in move_data_s3
    file_name = extract_data(api_url)
  File "task/weather_extraction.py", line 69, in extract_data
    desired_timezone = pytz.timezone('Asia/Hanoi')  # Replace with your desired time zone
  File "/home/airflow/.local/lib/python3.7/site-packages/pytz/__init__.py", line 188, in timezone
    raise UnknownTimeZoneError(zone)
pytz.exceptions.UnknownTimeZoneError: 'Asia/Hanoi'
[2023-09-10T18:29:56.557+0000] {taskinstance.py:1412} INFO - Marking task as UP_FOR_RETRY. dag_id=weather_pipeline, task_id=move_data, execution_date=20230910T182419, start_date=20230910T182956, end_date=20230910T182956
[2023-09-10T18:29:56.570+0000] {standard_task_runner.py:97} ERROR - Failed to execute job 53 for task move_data ('Asia/Hanoi'; 2035)
[2023-09-10T18:29:56.607+0000] {local_task_job.py:156} INFO - Task exited with return code 1
[2023-09-10T18:29:56.643+0000] {local_task_job.py:279} INFO - 0 downstream tasks scheduled from follow-on schedule check
